Workbook

Sheet Instrucciones
A1: MiRiskSim – Simulación Monte Carlo de un proyecto
A3: Qué es | B3: Simulador de riesgo para evaluación de proyectos hecho solo con fórmulas (sin macros). Funciona en Excel (Mac/Windows), LibreOffice y WPS.
A4: Cómo se usa | B4: 1) Ve a la hoja 'Supuestos' y edita las celdas azules/amarillas: distribución y parámetros de cada variable incierta. 2) Ve a 'Resultados': ahí aparecen estadísticos, probabilidades, histograma y sensibilidad. 3) Para volver a simular pulsa F9 (Excel Mac: fn+F9 o Cmd+=; LibreOffice: Ctrl+Shift+F9). Cada recálculo = 1000 nuevas corridas.
A5: Modelo incluido | B5: Flujo de caja a 5 años: Ingresos_t = Ingresos_1 × (1+g)^(t-1); Flujo_t = Ingresos_t × (1 − Costos%) × (1 − Impuesto); año 5 suma el valor de rescate. VAN = −Inversión + Σ Flujo_t /(1+r)^t. TIR calculada por cada corrida.
A6: Distribuciones | B6: Normal (P1=media, P2=desv. estándar) · Triangular (P1=mínimo, P2=más probable, P3=máximo) · Uniforme (P1=mínimo, P2=máximo) · Lognormal (P1=media, P2=desv. estándar, ambas de la variable) · Fija (P1=valor).
A7: Truncar | B7: Las columnas Mín/Máx recortan los valores simulados (por ejemplo, una tasa no puede ser negativa). Déjalas vacías si no quieres límites.
A8: Congelar resultados | B8: RAND() cambia en cada recálculo. Para guardar una corrida para tu informe: selecciona Simulacion!I5:W1004, copia y pega como VALORES, o toma capturas.
A9: Otro modelo | B9: Para tu propio proyecto cambia las fórmulas de las columnas P:W de la hoja 'Simulacion' (flujos, VAN, TIR) y agrega/quita variables en 'Supuestos'. Más corridas: arrastra hacia abajo la última fila de 'Simulacion' y amplía los rangos en 'Resultados'.
A10: Limitaciones | B10: No incluye correlaciones entre variables ni optimización/pronóstico de series de tiempo como Risk Simulator. Las variables se muestrean de forma independiente.
A11: Colores | B11: Texto azul = dato que puedes editar · Fondo amarillo = supuesto clave · Texto negro = fórmula.

Sheet Resultados
A1: Resultados de la simulación
A2: Pulsa F9 para generar una nueva simulación. Los valores cambian ligeramente en cada corrida (es normal).
A4: Estadístico (VAN) | B4: Valor | D4: Percentil | E4: VAN | F4: TIR
A5: Nº de simulaciones | B5: =COUNT(Simulacion!$V$5:$V$1004) | D5: 0.01 | E5: =PERCENTILE(Simulacion!$V$5:$V$1004,D5) | F5: =IFERROR(PERCENTILE(Simulacion!$W$5:$W$1004,D5),"n/d")
A6: VAN determinista (caso base) | B6: =Supuestos!B21 | D6: 0.05 | E6: =PERCENTILE(Simulacion!$V$5:$V$1004,D6) | F6: =IFERROR(PERCENTILE(Simulacion!$W$5:$W$1004,D6),"n/d")
A7: Media | B7: =AVERAGE(Simulacion!$V$5:$V$1004) | D7: 0.1 | E7: =PERCENTILE(Simulacion!$V$5:$V$1004,D7) | F7: =IFERROR(PERCENTILE(Simulacion!$W$5:$W$1004,D7),"n/d")
A8: Mediana | B8: =MEDIAN(Simulacion!$V$5:$V$1004) | D8: 0.25 | E8: =PERCENTILE(Simulacion!$V$5:$V$1004,D8) | F8: =IFERROR(PERCENTILE(Simulacion!$W$5:$W$1004,D8),"n/d")
A9: Desviación estándar | B9: =STDEV(Simulacion!$V$5:$V$1004) | D9: 0.5 | E9: =PERCENTILE(Simulacion!$V$5:$V$1004,D9) | F9: =IFERROR(PERCENTILE(Simulacion!$W$5:$W$1004,D9),"n/d")
A10: Coeficiente de variación | B10: =IFERROR(B9/B7,"n/d") | D10: 0.75 | E10: =PERCENTILE(Simulacion!$V$5:$V$1004,D10) | F10: =IFERROR(PERCENTILE(Simulacion!$W$5:$W$1004,D10),"n/d")
A11: Mínimo | B11: =MIN(Simulacion!$V$5:$V$1004) | D11: 0.9 | E11: =PERCENTILE(Simulacion!$V$5:$V$1004,D11) | F11: =IFERROR(PERCENTILE(Simulacion!$W$5:$W$1004,D11),"n/d")
A12: Máximo | B12: =MAX(Simulacion!$V$5:$V$1004) | D12: 0.95 | E12: =PERCENTILE(Simulacion!$V$5:$V$1004,D12) | F12: =IFERROR(PERCENTILE(Simulacion!$W$5:$W$1004,D12),"n/d")
A13: Asimetría (skew) | B13: =SKEW(Simulacion!$V$5:$V$1004) | D13: 0.99 | E13: =PERCENTILE(Simulacion!$V$5:$V$1004,D13) | F13: =IFERROR(PERCENTILE(Simulacion!$W$5:$W$1004,D13),"n/d")
A14: Curtosis (exceso) | B14: =KURT(Simulacion!$V$5:$V$1004)
A15: IC 95% de la media – inferior | B15: =B7-1.96*B9/SQRT(B5) | D15: TIR media | F15: =IFERROR(AVERAGE(Simulacion!$W$5:$W$1004),"n/d")
A16: IC 95% de la media – superior | B16: =B7+1.96*B9/SQRT(B5) | D16: TIR determinista | F16: =Supuestos!B22
A17: Prob. VAN < 0 (pérdida) | B17: =COUNTIF(Simulacion!$V$5:$V$1004,"<0")/COUNT(Simulacion!$V$5:$V$1004) | D17: Corridas con TIR válida | F17: =COUNT(Simulacion!$W$5:$W$1004)
A18: Prob. VAN ≥ 0 (proyecto viable) | B18: =1-B17
A19: Valor objetivo del VAN (edítalo) | B19: 20000
A20: Prob. VAN ≥ valor objetivo | B20: =COUNTIF(Simulacion!$V$5:$V$1004,">="&B19)/COUNT(Simulacion!$V$5:$V$1004)
A23: Histograma del VAN
A24: Desde | B24: Hasta | C24: Centro | D24: Frecuencia | E24: % corridas | F24: % acumulado
A25: =$B$11 | B25: =A25+($B$12-$B$11)/20 | C25: =TEXT((A25+B25)/2,"#,##0") | D25: =COUNTIFS(Simulacion!$V$5:$V$1004,">="&A25,Simulacion!$V$5:$V$1004,"<"&B25) | E25: =D25/$B$5 | F25: =SUM($E$25:E25)
A26: =B25 | B26: =A26+($B$12-$B$11)/20 | C26: =TEXT((A26+B26)/2,"#,##0") | D26: =COUNTIFS(Simulacion!$V$5:$V$1004,">="&A26,Simulacion!$V$5:$V$1004,"<"&B26) | E26: =D26/$B$5 | F26: =SUM($E$25:E26)
A27: =B26 | B27: =A27+($B$12-$B$11)/20 | C27: =TEXT((A27+B27)/2,"#,##0") | D27: =COUNTIFS(Simulacion!$V$5:$V$1004,">="&A27,Simulacion!$V$5:$V$1004,"<"&B27) | E27: =D27/$B$5 | F27: =SUM($E$25:E27)
A28: =B27 | B28: =A28+($B$12-$B$11)/20 | C28: =TEXT((A28+B28)/2,"#,##0") | D28: =COUNTIFS(Simulacion!$V$5:$V$1004,">="&A28,Simulacion!$V$5:$V$1004,"<"&B28) | E28: =D28/$B$5 | F28: =SUM($E$25:E28)
A29: =B28 | B29: =A29+($B$12-$B$11)/20 | C29: =TEXT((A29+B29)/2,"#,##0") | D29: =COUNTIFS(Simulacion!$V$5:$V$1004,">="&A29,Simulacion!$V$5:$V$1004,"<"&B29) | E29: =D29/$B$5 | F29: =SUM($E$25:E29)
A30: =B29 | B30: =A30+($B$12-$B$11)/20 | C30: =TEXT((A30+B30)/2,"#,##0") | D30: =COUNTIFS(Simulacion!$V$5:$V$1004,">="&A30,Simulacion!$V$5:$V$1004,"<"&B30) | E30: =D30/$B$5 | F30: =SUM($E$25:E30)
A31: =B30 | B31: =A31+($B$12-$B$11)/20 | C31: =TEXT((A31+B31)/2,"#,##0") | D31: =COUNTIFS(Simulacion!$V$5:$V$1004,">="&A31,Simulacion!$V$5:$V$1004,"<"&B31) | E31: =D31/$B$5 | F31: =SUM($E$25:E31)
A32: =B31 | B32: =A32+($B$12-$B$11)/20 | C32: =TEXT((A32+B32)/2,"#,##0") | D32: =COUNTIFS(Simulacion!$V$5:$V$1004,">="&A32,Simulacion!$V$5:$V$1004,"<"&B32) | E32: =D32/$B$5 | F32: =SUM($E$25:E32)
A33: =B32 | B33: =A33+($B$12-$B$11)/20 | C33: =TEXT((A33+B33)/2,"#,##0") | D33: =COUNTIFS(Simulacion!$V$5:$V$1004,">="&A33,Simulacion!$V$5:$V$1004,"<"&B33) | E33: =D33/$B$5 | F33: =SUM($E$25:E33)
A34: =B33 | B34: =A34+($B$12-$B$11)/20 | C34: =TEXT((A34+B34)/2,"#,##0") | D34: =COUNTIFS(Simulacion!$V$5:$V$1004,">="&A34,Simulacion!$V$5:$V$1004,"<"&B34) | E34: =D34/$B$5 | F34: =SUM($E$25:E34)
A35: =B34 | B35: =A35+($B$12-$B$11)/20 | C35: =TEXT((A35+B35)/2,"#,##0") | D35: =COUNTIFS(Simulacion!$V$5:$V$1004,">="&A35,Simulacion!$V$5:$V$1004,"<"&B35) | E35: =D35/$B$5 | F35: =SUM($E$25:E35)
A36: =B35 | B36: =A36+($B$12-$B$11)/20 | C36: =TEXT((A36+B36)/2,"#,##0") | D36: =COUNTIFS(Simulacion!$V$5:$V$1004,">="&A36,Simulacion!$V$5:$V$1004,"<"&B36) | E36: =D36/$B$5 | F36: =SUM($E$25:E36)
A37: =B36 | B37: =A37+($B$12-$B$11)/20 | C37: =TEXT((A37+B37)/2,"#,##0") | D37: =COUNTIFS(Simulacion!$V$5:$V$1004,">="&A37,Simulacion!$V$5:$V$1004,"<"&B37) | E37: =D37/$B$5 | F37: =SUM($E$25:E37)
... A43: =B42 | B43: =A43+($B$12-$B$11)/20 | C43: =TEXT((A43+B43)/2,"#,##0") | D43: =COUNTIFS(Simulacion!$V$5:$V$1004,">="&A43,Simulacion!$V$5:$V$1004,"<"&B43) | E43: =D43/$B$5 | F43: =SUM($E$25:E43)
A44: =B43 | B44: =A44+($B$12-$B$11)/20 | C44: =TEXT((A44+B44)/2,"#,##0") | D44: =COUNTIFS(Simulacion!$V$5:$V$1004,">="&A44,Simulacion!$V$5:$V$1004,"<="&B44) | E44: =D44/$B$5 | F44: =SUM($E$25:E44)
A46: Sensibilidad: correlación de cada variable con el VAN
A47: Variable | B47: Correlación | C47: |Corr.|
A48: Inversión inicial | B48: =IFERROR(CORREL(Simulacion!$I$5:$I$1004,Simulacion!$V$5:$V$1004),0) | C48: =ABS(B48)
A49: Ingresos año 1 | B49: =IFERROR(CORREL(Simulacion!$J$5:$J$1004,Simulacion!$V$5:$V$1004),0) | C49: =ABS(B49)
...

Sheet Supuestos
A1: Supuestos y variables inciertas
A2: Edita las celdas azules. Los valores base alimentan el caso determinista; la simulación usa la distribución elegida.
A4: Variable | B4: Unidad | C4: Distribución | D4: P1 | E4: P2 | F4: P3 | G4: Mín (truncar) | H4: Máx (truncar) | I4: Valor base | J4: Significado de P1 / P2 / P3
A5: Inversión inicial | B5: u.m. | C5: Triangular | D5: 90000 | E5: 100000 | F5: 125000 | I5: 100000 | J5: =IF(C5="Triangular","mín / más probable / máx",IF(C5="Normal","media / desv. estándar",IF(C5="Uniforme","mín / máx",IF(C5="Lognormal","media / desv. estándar","valor"))))
A6: Ingresos año 1 | B6: u.m. | C6: Normal | D6: 65000 | E6: 10000 | G6: 0 | I6: 65000 | J6: =IF(C6="Triangular","mín / más probable / máx",IF(C6="Normal","media / desv. estándar",IF(C6="Uniforme","mín / máx",IF(C6="Lognormal","media / desv. estándar","valor"))))
A7: Crecimiento anual ingresos | B7: % | C7: Uniforme | D7: 0 | E7: 0.08 | I7: 0.04 | J7: =IF(C7="Triangular","mín / más probable / máx",IF(C7="Normal","media / desv. estándar",IF(C7="Uniforme","mín / máx",IF(C7="Lognormal","media / desv. estándar","valor"))))
A8: Costos (% de ingresos) | B8: % | C8: Triangular | D8: 0.38 | E8: 0.45 | F8: 0.6 | G8: 0 | H8: 1 | I8: 0.45 | J8: =IF(C8="Triangular","mín / más probable / máx",IF(C8="Normal","media / desv. estándar",IF(C8="Uniforme","mín / máx",IF(C8="Lognormal","media / desv. estándar","valor"))))
A9: Tasa de impuesto | B9: % | C9: Fija | D9: 0.25 | I9: 0.25 | J9: =IF(C9="Triangular","mín / más probable / máx",IF(C9="Normal","media / desv. estándar",IF(C9="Uniforme","mín / máx",IF(C9="Lognormal","media / desv. estándar","valor"))))
A10: Tasa de descuento | B10: % | C10: Normal | D10: 0.12 | E10: 0.015 | G10: 0.01 | I10: 0.12 | J10: =IF(C10="Triangular","mín / más probable / máx",IF(C10="Normal","media / desv. estándar",IF(C10="Uniforme","mín / máx",IF(C10="Lognormal","media / desv. estándar","valor"))))
A11: Valor de rescate (año 5) | B11: u.m. | C11: Lognormal | D11: 15000 | E11: 5000 | G11: 0 | I11: 15000 | J11: =IF(C11="Triangular","mín / más probable / máx",IF(C11="Normal","media / desv. estándar",IF(C11="Uniforme","mín / máx",IF(C11="Lognormal","media / desv. estándar","valor"))))
A13: Nota: 'u.m.' = unidades monetarias (usa tu moneda). Valores de ejemplo, reemplázalos por los de tu proyecto.
A15: Caso determinista (con valores base)
A16: Concepto | B16: Año 0 | C16: Año 1 | D16: Año 2 | E16: Año 3 | F16: Año 4 | G16: Año 5
A17: Ingresos | B17: 0 | C17: =$I$6*(1+$I$7)^(1-1) | D17: =$I$6*(1+$I$7)^(2-1) | E17: =$I$6*(1+$I$7)^(3-1) | F17: =$I$6*(1+$I$7)^(4-1) | G17: =$I$6*(1+$I$7)^(5-1)
A18: Flujo neto | B18: =-$I$5 | C18: =C17*(1-$I$8)*(1-$I$9) | D18: =D17*(1-$I$8)*(1-$I$9) | E18: =E17*(1-$I$8)*(1-$I$9) | F18: =F17*(1-$I$8)*(1-$I$9) | G18: =G17*(1-$I$8)*(1-$I$9)+$I$11
A19: Flujo para TIR/VAN | B19: =B18 | C19: =C18 | D19: =D18 | E19: =E18 | F19: =F18 | G19: =G18
A21: VAN base | B21: =B19+NPV($I$10,C19:G19)
A22: TIR base | B22: =IFERROR(IRR(B19:G19,0.1),"n/d")

Sheet Simulacion
A1: Corridas Monte Carlo (cada fila es un escenario completo)
A2: Se recalcula con F9. Columnas B:H = números aleatorios · I:O = valores muestreados · P:U = flujos · V = VAN · W = TIR
A4: # | B4: U Inversión inic | C4: U Ingresos año 1 | D4: U Crecimiento an | E4: U Costos (% de i | F4: U Tasa de impues | G4: U Tasa de descue | H4: U Valor de resca | I4: Inversión inicial | J4: Ingresos año 1 | K4: Crecimiento anual ingresos | L4: Costos (% de ingresos) | M4: Tasa de impuesto | N4: Tasa de descuento | O4: Valor de rescate (año 5) | P4: Flujo 0 | Q4: Flujo 1 | R4: Flujo 2 | S4: Flujo 3 | T4: Flujo 4 | U4: Flujo 5 | V4: VAN | W4: TIR
A5: 1 | B5: =RAND()*(1-2E-6)+1E-6 | C5: =RAND()*(1-2E-6)+1E-6 | D5: =RAND()*(1-2E-6)+1E-6 | E5: =RAND()*(1-2E-6)+1E-6 | F5: =RAND()*(1-2E-6)+1E-6 | G5: =RAND()*(1-2E-6)+1E-6 | H5: =RAND()*(1-2E-6)+1E-6 | I5: =MIN(IF(Supuestos!$H$5="",1E+99,Supuestos!$H$5),MAX(IF(Supuestos!$G$5="",-1E+99,Supuestos!$G$5),IF(Supuestos!$C$5="Normal",NORMINV(B5,Supuestos!$D$5,Supuestos!$E$5),IF(Supuestos!$C$5="Triangular",IF(B5<(Supuestos!$E$5-Supuestos!$D$5)/(Supuestos!$F$5-Supuestos!$D$5),Supuestos!$D$5+SQRT(B5*(Supuestos!$F$5-Supuestos!$D$5)*(Supuestos!$E$5-Supuestos!$D$5)),Supuestos!$F$5-SQRT((1-B5)*(Supuestos!$F$5-Supuestos!$D$5)*(Supuestos!$F$5-Supuestos!$E$5))),IF(Supuestos!$C$5="Uniforme",Supuestos!$D$5+B5*(Supuestos!$E$5-Supuestos!$D$5),IF(Supuestos!$C$5="Lognormal",LOGINV(B5,LN(Supuestos!$D$5)-LN(1+Supuestos!$E$5^2/Supuestos!$D$5^2)/2,SQRT(LN(1+Supuestos!$E$5^2/Supuestos!$D$5^2))),Supuestos!$D$5)))))) | J5: =MIN(IF(Supuestos!$H$6="",1E+99,Supuestos!$H$6),MAX(IF(Supuestos!$G$6="",-1E+99,Supuestos!$G$6),IF(Supuestos!$C$6="Normal",NORMINV(C5,Supuestos!$D$6,Supuestos!$E$6),IF(Supuestos!$C$6="Triangular",IF(C5<(Supuestos!$E$6-Supuestos!$D$6)/(Supuestos!$F$6-Supuestos!$D$6),Supuestos!$D$6+SQRT(C5*(Supuestos!$F$6-Supuestos!$D$6)*(Supuestos!$E$6-Supuestos!$D$6)),Supuestos!$F$6-SQRT((1-C5)*(Supuestos!$F$6-Supuestos!$D$6)*(Supuestos!$F$6-Supuestos!$E$6))),IF(Supuestos!$C$6="Uniforme",Supuestos!$D$6+C5*(Supuestos!$E$6-Supuestos!$D$6),IF(Supuestos!$C$6="Lognormal",LOGINV(C5,LN(Supuestos!$D$6)-LN(1+Supuestos!$E$6^2/Supuestos!$D$6^2)/2,SQRT(LN(1+Supuestos!$E$6^2/Supuestos!$D$6^2))),Supuestos!$D$6)))))) | K5: =MIN(IF(Supuestos!$H$7="",1E+99,Supuestos!$H$7),MAX(IF(Supuestos!$G$7="",-1E+99,Supuestos!$G$7),IF(Supuestos!$C$7="Normal",NORMINV(D5,Supuestos!$D$7,Supuestos!$E$7),IF(Supuestos!$C$7="Triangular",IF(D5<(Supuestos!$E$7-Supuestos!$D$7)/(Supuestos!$F$7-Supuestos!$D$7),Supuestos!$D$7+SQRT(D5*(Supuestos!$F$7-Supuestos!$D$7)*(Supuestos!$E$7-Supuestos!$D$7)),Supuestos!$F$7-SQRT((1-D5)*(Supuestos!$F$7-Supuestos!$D$7)*(Supuestos!$F$7-Supuestos!$E$7))),IF(Supuestos!$C$7="Uniforme",Supuestos!$D$7+D5*(Supuestos!$E$7-Supuestos!$D$7),IF(Supuestos!$C$7="Lognormal",LOGINV(D5,LN(Supuestos!$D$7)-LN(1+Supuestos!$E$7^2/Supuestos!$D$7^2)/2,SQRT(LN(1+Supuestos!$E$7^2/Supuestos!$D$7^2))),Supuestos!$D$7)))))) | L5: =MIN(IF(Supuestos!$H$8="",1E+99,Supuestos!$H$8),MAX(IF(Supuestos!$G$8="",-1E+99,Supuestos!$G$8),IF(Supuestos!$C$8="Normal",NORMINV(E5,Supuestos!$D$8,Supuestos!$E$8),IF(Supuestos!$C$8="Triangular",IF(E5<(Supuestos!$E$8-Supuestos!$D$8)/(Supuestos!$F$8-Supuestos!$D$8),Supuestos!$D$8+SQRT(E5*(Supuestos!$F$8-Supuestos!$D$8)*(Supuestos!$E$8-Supuestos!$D$8)),Supuestos!$F$8-SQRT((1-E5)*(Supuestos!$F$8-Supuestos!$D$8)*(Supuestos!$F$8-Supuestos!$E$8))),IF(Supuestos!$C$8="Uniforme",Supuestos!$D$8+E5*(Supuestos!$E$8-Supuestos!$D$8),IF(Supuestos!$C$8="Lognormal",LOGINV(E5,LN(Supuestos!$D$8)-LN(1+Supuestos!$E$8^2/Supuestos!$D$8^2)/2,SQRT(LN(1+Supuestos!$E$8^2/Supuestos!$D$8^2))),Supuestos!$D$8)))))) | M5: =MIN(IF(Supuestos!$H$9="",1E+99,Supuestos!$H$9),MAX(IF(Supuestos!$G$9="",-1E+99,Supuestos!$G$9),IF(Supuestos!$C$9="Normal",NORMINV(F5,Supuestos!$D$9,Supuestos!$E$9),IF(Supuestos!$C$9="Triangular",IF(F5<(Supuestos!$E$9-Supuestos!$D$9)/(Supuestos!$F$9-Supuestos!$D$9),Supuestos!$D$9+SQRT(F5*(Supuestos!$F$9-Supuestos!$D$9)*(Supuestos!$E$9-Supuestos!$D$9)),Supuestos!$F$9-SQRT((1-F5)*(Supuestos!$F$9-Supuestos!$D$9)*(Supuestos!$F$9-Supuestos!$E$9))),IF(Supuestos!$C$9="Uniforme",Supuestos!$D$9+F5*(Supuestos!$E$9-Supuestos!$D$9),IF(Supuestos!$C$9="Lognormal",LOGINV(F5,LN(Supuestos!$D$9)-LN(1+Supuestos!$E$9^2/Supuestos!$D$9^2)/2,SQRT(LN(1+Supuestos!$E$9^2/Supuestos!$D$9^2))),Supuestos!$D$9)))))) | N5: =MIN(IF(Supuestos!$H$10="",1E+99,Supuestos!$H$10),MAX(IF(Supuestos!$G$10="",-1E+99,Supuestos!$G$10),IF(Supuestos!$C$10="Normal",NORMINV(G5,Supuestos!$D$10,Supuestos!$E$10),IF(Supuestos!$C$10="Triangular",IF(G5<(Supuestos!$E$10-Supuestos!$D$10)/(Supuestos!$F$10-Supuestos!$D$10),Supuestos!$D$10+SQRT(G5*(Supuestos!$F$10-Supuestos!$D$10)*(Supuestos!$E$10-Supuestos!$D$10)),Supuestos!$F$10-SQRT((1-G5)*(Supuestos!$F$10-Supuestos!$D$10)*(Supuestos!$F$10-Supuestos!$E$10))),IF(Supuestos!$C$10="Uniforme",Supuestos!$D$10+G5*(Supuestos!$E$10-Supuestos!$D$10),IF(Supuestos!$C$10="Lognormal",LOGINV(G5,LN(Supuestos!$D$10)-LN(1+Supuestos!$E$10^2/Supuestos!$D$10^2)/2,SQRT(LN(1+Supuestos!$E$10^2/Supuestos!$D$10^2))),Supuestos!$D$10)))))) | O5: =MIN(IF(Supuestos!$H$11="",1E+99,Supuestos!$H$11),MAX(IF(Supuestos!$G$11="",-1E+99,Supuestos!$G$11),IF(Supuestos!$C$11="Normal",NORMINV(H5,Supuestos!$D$11,Supuestos!$E$11),IF(Supuestos!$C$11="Triangular",IF(H5<(Supuestos!$E$11-Supuestos!$D$11)/(Supuestos!$F$11-Supuestos!$D$11),Supuestos!$D$11+SQRT(H5*(Supuestos!$F$11-Supuestos!$D$11)*(Supuestos!$E$11-Supuestos!$D$11)),Supuestos!$F$11-SQRT((1-H5)*(Supuestos!$F$11-Supuestos!$D$11)*(Supuestos!$F$11-Supuestos!$E$11))),IF(Supuestos!$C$11="Uniforme",Supuestos!$D$11+H5*(Supuestos!$E$11-Supuestos!$D$11),IF(Supuestos!$C$11="Lognormal",LOGINV(H5,LN(Supuestos!$D$11)-LN(1+Supuestos!$E$11^2/Supuestos!$D$11^2)/2,SQRT(LN(1+Supuestos!$E$11^2/Supuestos!$D$11^2))),Supuestos!$D$11)))))) | P5: =-I5 | Q5: =$J5*(1+$K5)^(1-1)*(1-$L5)*(1-$M5) | R5: =$J5*(1+$K5)^(2-1)*(1-$L5)*(1-$M5) | S5: =$J5*(1+$K5)^(3-1)*(1-$L5)*(1-$M5) | T5: =$J5*(1+$K5)^(4-1)*(1-$L5)*(1-$M5) | U5: =$J5*(1+$K5)^(5-1)*(1-$L5)*(1-$M5)+$O5 | V5: =P5+NPV($N5,Q5:U5) | W5: =IFERROR(IRR(P5:U5,0.1),"")
A6: 2 | B6: =RAND()*(1-2E-6)+1E-6 | C6: =RAND()*(1-2E-6)+1E-6 | D6: =RAND()*(1-2E-6)+1E-6 | E6: =RAND()*(1-2E-6)+1E-6 | F6: =RAND()*(1-2E-6)+1E-6 | G6: =RAND()*(1-2E-6)+1E-6 | H6: =RAND()*(1-2E-6)+1E-6 | I6: =MIN(IF(Supuestos!$H$5="",1E+99,Supuestos!$H$5),MAX(IF(Supuestos!$G$5="",-1E+99,Supuestos!$G$5),IF(Supuestos!$C$5="Normal",NORMINV(B6,Supuestos!$D$5,Supuestos!$E$5),IF(Supuestos!$C$5="Triangular",IF(B6<(Supuestos!$E$5-Supuestos!$D$5)/(Supuestos!$F$5-Supuestos!$D$5),Supuestos!$D$5+SQRT(B6*(Supuestos!$F$5-Supuestos!$D$5)*(Supuestos!$E$5-Supuestos!$D$5)),Supuestos!$F$5-SQRT((1-B6)*(Supuestos!$F$5-Supuestos!$D$5)*(Supuestos!$F$5-Supuestos!$E$5))),IF(Supuestos!$C$5="Uniforme",Supuestos!$D$5+B6*(Supuestos!$E$5-Supuestos!$D$5),IF(Supuestos!$C$5="Lognormal",LOGINV(B6,LN(Supuestos!$D$5)-LN(1+Supuestos!$E$5^2/Supuestos!$D$5^2)/2,SQRT(LN(1+Supuestos!$E$5^2/Supuestos!$D$5^2))),Supuestos!$D$5)))))) | J6: =MIN(IF(Supuestos!$H$6="",1E+99,Supuestos!$H$6),MAX(IF(Supuestos!$G$6="",-1E+99,Supuestos!$G$6),IF(Supuestos!$C$6="Normal",NORMINV(C6,Supuestos!$D$6,Supuestos!$E$6),IF(Supuestos!$C$6="Triangular",IF(C6<(Supuestos!$E$6-Supuestos!$D$6)/(Supuestos!$F$6-Supuestos!$D$6),Supuestos!$D$6+SQRT(C6*(Supuestos!$F$6-Supuestos!$D$6)*(Supuestos!$E$6-Supuestos!$D$6)),Supuestos!$F$6-SQRT((1-C6)*(Supuestos!$F$6-Supuestos!$D$6)*(Supuestos!$F$6-Supuestos!$E$6))),IF(Supuestos!$C$6="Uniforme",Supuestos!$D$6+C6*(Supuestos!$E$6-Supuestos!$D$6),IF(Supuestos!$C$6="Lognormal",LOGINV(C6,LN(Supuestos!$D$6)-LN(1+Supuestos!$E$6^2/Supuestos!$D$6^2)/2,SQRT(LN(1+Supuestos!$E$6^2/Supuestos!$D$6^2))),Supuestos!$D$6)))))) | K6: =MIN(IF(Supuestos!$H$7="",1E+99,Supuestos!$H$7),MAX(IF(Supuestos!$G$7="",-1E+99,Supuestos!$G$7),IF(Supuestos!$C$7="Normal",NORMINV(D6,Supuestos!$D$7,Supuestos!$E$7),IF(Supuestos!$C$7="Triangular",IF(D6<(Supuestos!$E$7-Supuestos!$D$7)/(Supuestos!$F$7-Supuestos!$D$7),Supuestos!$D$7+SQRT(D6*(Supuestos!$F$7-Supuestos!$D$7)*(Supuestos!$E$7-Supuestos!$D$7)),Supuestos!$F$7-SQRT((1-D6)*(Supuestos!$F$7-Supuestos!$D$7)*(Supuestos!$F$7-Supuestos!$E$7))),IF(Supuestos!$C$7="Uniforme",Supuestos!$D$7+D6*(Supuestos!$E$7-Supuestos!$D$7),IF(Supuestos!$C$7="Lognormal",LOGINV(D6,LN(Supuestos!$D$7)-LN(1+Supuestos!$E$7^2/Supuestos!$D$7^2)/2,SQRT(LN(1+Supuestos!$E$7^2/Supuestos!$D$7^2))),Supuestos!$D$7)))))) | L6: =MIN(IF(Supuestos!$H$8="",1E+99,Supuestos!$H$8),MAX(IF(Supuestos!$G$8="",-1E+99,Supuestos!$G$8),IF(Supuestos!$C$8="Normal",NORMINV(E6,Supuestos!$D$8,Supuestos!$E$8),IF(Supuestos!$C$8="Triangular",IF(E6<(Supuestos!$E$8-Supuestos!$D$8)/(Supuestos!$F$8-Supuestos!$D$8),Supuestos!$D$8+SQRT(E6*(Supuestos!$F$8-Supuestos!$D$8)*(Supuestos!$E$8-Supuestos!$D$8)),Supuestos!$F$8-SQRT((1-E6)*(Supuestos!$F$8-Supuestos!$D$8)*(Supuestos!$F$8-Supuestos!$E$8))),IF(Supuestos!$C$8="Uniforme",Supuestos!$D$8+E6*(Supuestos!$E$8-Supuestos!$D$8),IF(Supuestos!$C$8="Lognormal",LOGINV(E6,LN(Supuestos!$D$8)-LN(1+Supuestos!$E$8^2/Supuestos!$D$8^2)/2,SQRT(LN(1+Supuestos!$E$8^2/Supuestos!$D$8^2))),Supuestos!$D$8)))))) | M6: =MIN(IF(Supuestos!$H$9="",1E+99,Supuestos!$H$9),MAX(IF(Supuestos!$G$9="",-1E+99,Supuestos!$G$9),IF(Supuestos!$C$9="Normal",NORMINV(F6,Supuestos!$D$9,Supuestos!$E$9),IF(Supuestos!$C$9="Triangular",IF(F6<(Supuestos!$E$9-Supuestos!$D$9)/(Supuestos!$F$9-Supuestos!$D$9),Supuestos!$D$9+SQRT(F6*(Supuestos!$F$9-Supuestos!$D$9)*(Supuestos!$E$9-Supuestos!$D$9)),Supuestos!$F$9-SQRT((1-F6)*(Supuestos!$F$9-Supuestos!$D$9)*(Supuestos!$F$9-Supuestos!$E$9))),IF(Supuestos!$C$9="Uniforme",Supuestos!$D$9+F6*(Supuestos!$E$9-Supuestos!$D$9),IF(Supuestos!$C$9="Lognormal",LOGINV(F6,LN(Supuestos!$D$9)-LN(1+Supuestos!$E$9^2/Supuestos!$D$9^2)/2,SQRT(LN(1+Supuestos!$E$9^2/Supuestos!$D$9^2))),Supuestos!$D$9)))))) | N6: =MIN(IF(Supuestos!$H$10="",1E+99,Supuestos!$H$10),MAX(IF(Supuestos!$G$10="",-1E+99,Supuestos!$G$10),IF(Supuestos!$C$10="Normal",NORMINV(G6,Supuestos!$D$10,Supuestos!$E$10),IF(Supuestos!$C$10="Triangular",IF(G6<(Supuestos!$E$10-Supuestos!$D$10)/(Supuestos!$F$10-Supuestos!$D$10),Supuestos!$D$10+SQRT(G6*(Supuestos!$F$10-Supuestos!$D$10)*(Supuestos!$E$10-Supuestos!$D$10)),Supuestos!$F$10-SQRT((1-G6)*(Supuestos!$F$10-Supuestos!$D$10)*(Supuestos!$F$10-Supuestos!$E$10))),IF(Supuestos!$C$10="Uniforme",Supuestos!$D$10+G6*(Supuestos!$E$10-Supuestos!$D$10),IF(Supuestos!$C$10="Lognormal",LOGINV(G6,LN(Supuestos!$D$10)-LN(1+Supuestos!$E$10^2/Supuestos!$D$10^2)/2,SQRT(LN(1+Supuestos!$E$10^2/Supuestos!$D$10^2))),Supuestos!$D$10)))))) | O6: =MIN(IF(Supuestos!$H$11="",1E+99,Supuestos!$H$11),MAX(IF(Supuestos!$G$11="",-1E+99,Supuestos!$G$11),IF(Supuestos!$C$11="Normal",NORMINV(H6,Supuestos!$D$11,Supuestos!$E$11),IF(Supuestos!$C$11="Triangular",IF(H6<(Supuestos!$E$11-Supuestos!$D$11)/(Supuestos!$F$11-Supuestos!$D$11),Supuestos!$D$11+SQRT(H6*(Supuestos!$F$11-Supuestos!$D$11)*(Supuestos!$E$11-Supuestos!$D$11)),Supuestos!$F$11-SQRT((1-H6)*(Supuestos!$F$11-Supuestos!$D$11)*(Supuestos!$F$11-Supuestos!$E$11))),IF(Supuestos!$C$11="Uniforme",Supuestos!$D$11+H6*(Supuestos!$E$11-Supuestos!$D$11),IF(Supuestos!$C$11="Lognormal",LOGINV(H6,LN(Supuestos!$D$11)-LN(1+Supuestos!$E$11^2/Supuestos!$D$11^2)/2,SQRT(LN(1+Supuestos!$E$11^2/Supuestos!$D$11^2))),Supuestos!$D$11)))))) | P6: =-I6 | Q6: =$J6*(1+$K6)^(1-1)*(1-$L6)*(1-$M6) | R6: =$J6*(1+$K6)^(2-1)*(1-$L6)*(1-$M6) | S6: =$J6*(1+$K6)^(3-1)*(1-$L6)*(1-$M6) | T6: =$J6*(1+$K6)^(4-1)*(1-$L6)*(1-$M6) | U6: =$J6*(1+$K6)^(5-1)*(1-$L6)*(1-$M6)+$O6 | V6: =P6+NPV($N6,Q6:U6) | W6: =IFERROR(IRR(P6:U6,0.1),"")
A7: 3 | B7: =RAND()*(1-2E-6)+1E-6 | C7: =RAND()*(1-2E-6)+1E-6 | D7: =RAND()*(1-2E-6)+1E-6 | E7: =RAND()*(1-2E-6)+1E-6 | F7: =RAND()*(1-2E-6)+1E-6 | G7: =RAND()*(1-2E-6)+1E-6 | H7: =RAND()*(1-2E-6)+1E-6 | I7: =MIN(IF(Supuestos!$H$5="",1E+99,Supuestos!$H$5),MAX(IF(Supuestos!$G$5="",-1E+99,Supuestos!$G$5),IF(Supuestos!$C$5="Normal",NORMINV(B7,Supuestos!$D$5,Supuestos!$E$5),IF(Supuestos!$C$5="Triangular",IF(B7<(Supuestos!$E$5-Supuestos!$D$5)/(Supuestos!$F$5-Supuestos!$D$5),Supuestos!$D$5+SQRT(B7*(Supuestos!$F$5-Supuestos!$D$5)*(Supuestos!$E$5-Supuestos!$D$5)),Supuestos!$F$5-SQRT((1-B7)*(Supuestos!$F$5-Supuestos!$D$5)*(Supuestos!$F$5-Supuestos!$E$5))),IF(Supuestos!$C$5="Uniforme",Supuestos!$D$5+B7*(Supuestos!$E$5-Supuestos!$D$5),IF(Supuestos!$C$5="Lognormal",LOGINV(B7,LN(Supuestos!$D$5)-LN(1+Supuestos!$E$5^2/Supuestos!$D$5^2)/2,SQRT(LN(1+Supuestos!$E$5^2/Supuestos!$D$5^2))),Supuestos!$D$5)))))) | J7: =MIN(IF(Supuestos!$H$6="",1E+99,Supuestos!$H$6),MAX(IF(Supuestos!$G$6="",-1E+99,Supuestos!$G$6),IF(Supuestos!$C$6="Normal",NORMINV(C7,Supuestos!$D$6,Supuestos!$E$6),IF(Supuestos!$C$6="Triangular",IF(C7<(Supuestos!$E$6-Supuestos!$D$6)/(Supuestos!$F$6-Supuestos!$D$6),Supuestos!$D$6+SQRT(C7*(Supuestos!$F$6-Supuestos!$D$6)*(Supuestos!$E$6-Supuestos!$D$6)),Supuestos!$F$6-SQRT((1-C7)*(Supuestos!$F$6-Supuestos!$D$6)*(Supuestos!$F$6-Supuestos!$E$6))),IF(Supuestos!$C$6="Uniforme",Supuestos!$D$6+C7*(Supuestos!$E$6-Supuestos!$D$6),IF(Supuestos!$C$6="Lognormal",LOGINV(C7,LN(Supuestos!$D$6)-LN(1+Supuestos!$E$6^2/Supuestos!$D$6^2)/2,SQRT(LN(1+Supuestos!$E$6^2/Supuestos!$D$6^2))),Supuestos!$D$6)))))) | K7: =MIN(IF(Supuestos!$H$7="",1E+99,Supuestos!$H$7),MAX(IF(Supuestos!$G$7="",-1E+99,Supuestos!$G$7),IF(Supuestos!$C$7="Normal",NORMINV(D7,Supuestos!$D$7,Supuestos!$E$7),IF(Supuestos!$C$7="Triangular",IF(D7<(Supuestos!$E$7-Supuestos!$D$7)/(Supuestos!$F$7-Supuestos!$D$7),Supuestos!$D$7+SQRT(D7*(Supuestos!$F$7-Supuestos!$D$7)*(Supuestos!$E$7-Supuestos!$D$7)),Supuestos!$F$7-SQRT((1-D7)*(Supuestos!$F$7-Supuestos!$D$7)*(Supuestos!$F$7-Supuestos!$E$7))),IF(Supuestos!$C$7="Uniforme",Supuestos!$D$7+D7*(Supuestos!$E$7-Supuestos!$D$7),IF(Supuestos!$C$7="Lognormal",LOGINV(D7,LN(Supuestos!$D$7)-LN(1+Supuestos!$E$7^2/Supuestos!$D$7^2)/2,SQRT(LN(1+Supuestos!$E$7^2/Supuestos!$D$7^2))),Supuestos!$D$7)))))) | L7: =MIN(IF(Supuestos!$H$8="",1E+99,Supuestos!$H$8),MAX(IF(Supuestos!$G$8="",-1E+99,Supuestos!$G$8),IF(Supuestos!$C$8="Normal",NORMINV(E7,Supuestos!$D$8,Supuestos!$E$8),IF(Supuestos!$C$8="Triangular",IF(E7<(Supuestos!$E$8-Supuestos!$D$8)/(Supuestos!$F$8-Supuestos!$D$8),Supuestos!$D$8+SQRT(E7*(Supuestos!$F$8-Supuestos!$D$8)*(Supuestos!$E$8-Supuestos!$D$8)),Supuestos!$F$8-SQRT((1-E7)*(Supuestos!$F$8-Supuestos!$D$8)*(Supuestos!$F$8-Supuestos!$E$8))),IF(Supuestos!$C$8="Uniforme",Supuestos!$D$8+E7*(Supuestos!$E$8-Supuestos!$D$8),IF(Supuestos!$C$8="Lognormal",LOGINV(E7,LN(Supuestos!$D$8)-LN(1+Supuestos!$E$8^2/Supuestos!$D$8^2)/2,SQRT(LN(1+Supuestos!$E$8^2/Supuestos!$D$8^2))),Supuestos!$D$8)))))) | M7: =MIN(IF(Supuestos!$H$9="",1E+99,Supuestos!$H$9),MAX(IF(Supuestos!$G$9="",-1E+99,Supuestos!$G$9),IF(Supuestos!$C$9="Normal",NORMINV(F7,Supuestos!$D$9,Supuestos!$E$9),IF(Supuestos!$C$9="Triangular",IF(F7<(Supuestos!$E$9-Supuestos!$D$9)/(Supuestos!$F$9-Supuestos!$D$9),Supuestos!$D$9+SQRT(F7*(Supuestos!$F$9-Supuestos!$D$9)*(Supuestos!$E$9-Supuestos!$D$9)),Supuestos!$F$9-SQRT((1-F7)*(Supuestos!$F$9-Supuestos!$D$9)*(Supuestos!$F$9-Supuestos!$E$9))),IF(Supuestos!$C$9="Uniforme",Supuestos!$D$9+F7*(Supuestos!$E$9-Supuestos!$D$9),IF(Supuestos!$C$9="Lognormal",LOGINV(F7,LN(Supuestos!$D$9)-LN(1+Supuestos!$E$9^2/Supuestos!$D$9^2)/2,SQRT(LN(1+Supuestos!$E$9^2/Supuestos!$D$9^2))),Supuestos!$D$9)))))) | N7: =MIN(IF(Supuestos!$H$10="",1E+99,Supuestos!$H$10),MAX(IF(Supuestos!$G$10="",-1E+99,Supuestos!$G$10),IF(Supuestos!$C$10="Normal",NORMINV(G7,Supuestos!$D$10,Supuestos!$E$10),IF(Supuestos!$C$10="Triangular",IF(G7<(Supuestos!$E$10-Supuestos!$D$10)/(Supuestos!$F$10-Supuestos!$D$10),Supuestos!$D$10+SQRT(G7*(Supuestos!$F$10-Supuestos!$D$10)*(Supuestos!$E$10-Supuestos!$D$10)),Supuestos!$F$10-SQRT((1-G7)*(Supuestos!$F$10-Supuestos!$D$10)*(Supuestos!$F$10-Supuestos!$E$10))),IF(Supuestos!$C$10="Uniforme",Supuestos!$D$10+G7*(Supuestos!$E$10-Supuestos!$D$10),IF(Supuestos!$C$10="Lognormal",LOGINV(G7,LN(Supuestos!$D$10)-LN(1+Supuestos!$E$10^2/Supuestos!$D$10^2)/2,SQRT(LN(1+Supuestos!$E$10^2/Supuestos!$D$10^2))),Supuestos!$D$10)))))) | O7: =MIN(IF(Supuestos!$H$11="",1E+99,Supuestos!$H$11),MAX(IF(Supuestos!$G$11="",-1E+99,Supuestos!$G$11),IF(Supuestos!$C$11="Normal",NORMINV(H7,Supuestos!$D$11,Supuestos!$E$11),IF(Supuestos!$C$11="Triangular",IF(H7<(Supuestos!$E$11-Supuestos!$D$11)/(Supuestos!$F$11-Supuestos!$D$11),Supuestos!$D$11+SQRT(H7*(Supuestos!$F$11-Supuestos!$D$11)*(Supuestos!$E$11-Supuestos!$D$11)),Supuestos!$F$11-SQRT((1-H7)*(Supuestos!$F$11-Supuestos!$D$11)*(Supuestos!$F$11-Supuestos!$E$11))),IF(Supuestos!$C$11="Uniforme",Supuestos!$D$11+H7*(Supuestos!$E$11-Supuestos!$D$11),IF(Supuestos!$C$11="Lognormal",LOGINV(H7,LN(Supuestos!$D$11)-LN(1+Supuestos!$E$11^2/Supuestos!$D$11^2)/2,SQRT(LN(1+Supuestos!$E$11^2/Supuestos!$D$11^2))),Supuestos!$D$11)))))) | P7: =-I7 | Q7: =$J7*(1+$K7)^(1-1)*(1-$L7)*(1-$M7) | R7: =$J7*(1+$K7)^(2-1)*(1-$L7)*(1-$M7) | S7: =$J7*(1+$K7)^(3-1)*(1-$L7)*(1-$M7) | T7: =$J7*(1+$K7)^(4-1)*(1-$L7)*(1-$M7) | U7: =$J7*(1+$K7)^(5-1)*(1-$L7)*(1-$M7)+$O7 | V7: =P7+NPV($N7,Q7:U7) | W7: =IFERROR(IRR(P7:U7,0.1),"")
A8: 4 | B8: =RAND()*(1-2E-6)+1E-6 | C8: =RAND()*(1-2E-6)+1E-6 | D8: =RAND()*(1-2E-6)+1E-6 | E8: =RAND()*(1-2E-6)+1E-6 | F8: =RAND()*(1-2E-6)+1E-6 | G8: =RAND()*(1-2E-6)+1E-6 | H8: =RAND()*(1-2E-6)+1E-6 | I8: =MIN(IF(Supuestos!$H$5="",1E+99,Supuestos!$H$5),MAX(IF(Supuestos!$G$5="",-1E+99,Supuestos!$G$5),IF(Supuestos!$C$5="Normal",NORMINV(B8,Supuestos!$D$5,Supuestos!$E$5),IF(Supuestos!$C$5="Triangular",IF(B8<(Supuestos!$E$5-Supuestos!$D$5)/(Supuestos!$F$5-Supuestos!$D$5),Supuestos!$D$5+SQRT(B8*(Supuestos!$F$5-Supuestos!$D$5)*(Supuestos!$E$5-Supuestos!$D$5)),Supuestos!$F$5-SQRT((1-B8)*(Supuestos!$F$5-Supuestos!$D$5)*(Supuestos!$F$5-Supuestos!$E$5))),IF(Supuestos!$C$5="Uniforme",Supuestos!$D$5+B8*(Supuestos!$E$5-Supuestos!$D$5),IF(Supuestos!$C$5="Lognormal",LOGINV(B8,LN(Supuestos!$D$5)-LN(1+Supuestos!$E$5^2/Supuestos!$D$5^2)/2,SQRT(LN(1+Supuestos!$E$5^2/Supuestos!$D$5^2))),Supuestos!$D$5)))))) | J8: =MIN(IF(Supuestos!$H$6="",1E+99,Supuestos!$H$6),MAX(IF(Supuestos!$G$6="",-1E+99,Supuestos!$G$6),IF(Supuestos!$C$6="Normal",NORMINV(C8,Supuestos!$D$6,Supuestos!$E$6),IF(Supuestos!$C$6="Triangular",IF(C8<(Supuestos!$E$6-Supuestos!$D$6)/(Supuestos!$F$6-Supuestos!$D$6),Supuestos!$D$6+SQRT(C8*(Supuestos!$F$6-Supuestos!$D$6)*(Supuestos!$E$6-Supuestos!$D$6)),Supuestos!$F$6-SQRT((1-C8)*(Supuestos!$F$6-Supuestos!$D$6)*(Supuestos!$F$6-Supuestos!$E$6))),IF(Supuestos!$C$6="Uniforme",Supuestos!$D$6+C8*(Supuestos!$E$6-Supuestos!$D$6),IF(Supuestos!$C$6="Lognormal",LOGINV(C8,LN(Supuestos!$D$6)-LN(1+Supuestos!$E$6^2/Supuestos!$D$6^2)/2,SQRT(LN(1+Supuestos!$E$6^2/Supuestos!$D$6^2))),Supuestos!$D$6)))))) | K8: =MIN(IF(Supuestos!$H$7="",1E+99,Supuestos!$H$7),MAX(IF(Supuestos!$G$7="",-1E+99,Supuestos!$G$7),IF(Supuestos!$C$7="Normal",NORMINV(D8,Supuestos!$D$7,Supuestos!$E$7),IF(Supuestos!$C$7="Triangular",IF(D8<(Supuestos!$E$7-Supuestos!$D$7)/(Supuestos!$F$7-Supuestos!$D$7),Supuestos!$D$7+SQRT(D8*(Supuestos!$F$7-Supuestos!$D$7)*(Supuestos!$E$7-Supuestos!$D$7)),Supuestos!$F$7-SQRT((1-D8)*(Supuestos!$F$7-Supuestos!$D$7)*(Supuestos!$F$7-Supuestos!$E$7))),IF(Supuestos!$C$7="Uniforme",Supuestos!$D$7+D8*(Supuestos!$E$7-Supuestos!$D$7),IF(Supuestos!$C$7="Lognormal",LOGINV(D8,LN(Supuestos!$D$7)-LN(1+Supuestos!$E$7^2/Supuestos!$D$7^2)/2,SQRT(LN(1+Supuestos!$E$7^2/Supuestos!$D$7^2))),Supuestos!$D$7)))))) | L8: =MIN(IF(Supuestos!$H$8="",1E+99,Supuestos!$H$8),MAX(IF(Supuestos!$G$8="",-1E+99,Supuestos!$G$8),IF(Supuestos!$C$8="Normal",NORMINV(E8,Supuestos!$D$8,Supuestos!$E$8),IF(Supuestos!$C$8="Triangular",IF(E8<(Supuestos!$E$8-Supuestos!$D$8)/(Supuestos!$F$8-Supuestos!$D$8),Supuestos!$D$8+SQRT(E8*(Supuestos!$F$8-Supuestos!$D$8)*(Supuestos!$E$8-Supuestos!$D$8)),Supuestos!$F$8-SQRT((1-E8)*(Supuestos!$F$8-Supuestos!$D$8)*(Supuestos!$F$8-Supuestos!$E$8))),IF(Supuestos!$C$8="Uniforme",Supuestos!$D$8+E8*(Supuestos!$E$8-Supuestos!$D$8),IF(Supuestos!$C$8="Lognormal",LOGINV(E8,LN(Supuestos!$D$8)-LN(1+Supuestos!$E$8^2/Supuestos!$D$8^2)/2,SQRT(LN(1+Supuestos!$E$8^2/Supuestos!$D$8^2))),Supuestos!$D$8)))))) | M8: =MIN(IF(Supuestos!$H$9="",1E+99,Supuestos!$H$9),MAX(IF(Supuestos!$G$9="",-1E+99,Supuestos!$G$9),IF(Supuestos!$C$9="Normal",NORMINV(F8,Supuestos!$D$9,Supuestos!$E$9),IF(Supuestos!$C$9="Triangular",IF(F8<(Supuestos!$E$9-Supuestos!$D$9)/(Supuestos!$F$9-Supuestos!$D$9),Supuestos!$D$9+SQRT(F8*(Supuestos!$F$9-Supuestos!$D$9)*(Supuestos!$E$9-Supuestos!$D$9)),Supuestos!$F$9-SQRT((1-F8)*(Supuestos!$F$9-Supuestos!$D$9)*(Supuestos!$F$9-Supuestos!$E$9))),IF(Supuestos!$C$9="Uniforme",Supuestos!$D$9+F8*(Supuestos!$E$9-Supuestos!$D$9),IF(Supuestos!$C$9="Lognormal",LOGINV(F8,LN(Supuestos!$D$9)-LN(1+Supuestos!$E$9^2/Supuestos!$D$9^2)/2,SQRT(LN(1+Supuestos!$E$9^2/Supuestos!$D$9^2))),Supuestos!$D$9)))))) | N8: =MIN(IF(Supuestos!$H$10="",1E+99,Supuestos!$H$10),MAX(IF(Supuestos!$G$10="",-1E+99,Supuestos!$G$10),IF(Supuestos!$C$10="Normal",NORMINV(G8,Supuestos!$D$10,Supuestos!$E$10),IF(Supuestos!$C$10="Triangular",IF(G8<(Supuestos!$E$10-Supuestos!$D$10)/(Supuestos!$F$10-Supuestos!$D$10),Supuestos!$D$10+SQRT(G8*(Supuestos!$F$10-Supuestos!$D$10)*(Supuestos!$E$10-Supuestos!$D$10)),Supuestos!$F$10-SQRT((1-G8)*(Supuestos!$F$10-Supuestos!$D$10)*(Supuestos!$F$10-Supuestos!$E$10))),IF(Supuestos!$C$10="Uniforme",Supuestos!$D$10+G8*(Supuestos!$E$10-Supuestos!$D$10),IF(Supuestos!$C$10="Lognormal",LOGINV(G8,LN(Supuestos!$D$10)-LN(1+Supuestos!$E$10^2/Supuestos!$D$10^2)/2,SQRT(LN(1+Supuestos!$E$10^2/Supuestos!$D$10^2))),Supuestos!$D$10)))))) | O8: =MIN(IF(Supuestos!$H$11="",1E+99,Supuestos!$H$11),MAX(IF(Supuestos!$G$11="",-1E+99,Supuestos!$G$11),IF(Supuestos!$C$11="Normal",NORMINV(H8,Supuestos!$D$11,Supuestos!$E$11),IF(Supuestos!$C$11="Triangular",IF(H8<(Supuestos!$E$11-Supuestos!$D$11)/(Supuestos!$F$11-Supuestos!$D$11),Supuestos!$D$11+SQRT(H8*(Supuestos!$F$11-Supuestos!$D$11)*(Supuestos!$E$11-Supuestos!$D$11)),Supuestos!$F$11-SQRT((1-H8)*(Supuestos!$F$11-Supuestos!$D$11)*(Supuestos!$F$11-Supuestos!$E$11))),IF(Supuestos!$C$11="Uniforme",Supuestos!$D$11+H8*(Supuestos!$E$11-Supuestos!$D$11),IF(Supuestos!$C$11="Lognormal",LOGINV(H8,LN(Supuestos!$D$11)-LN(1+Supuestos!$E$11^2/Supuestos!$D$11^2)/2,SQRT(LN(1+Supuestos!$E$11^2/Supuestos!$D$11^2))),Supuestos!$D$11)))))) | P8: =-I8 | Q8: =$J8*(1+$K8)^(1-1)*(1-$L8)*(1-$M8) | R8: =$J8*(1+$K8)^(2-1)*(1-$L8)*(1-$M8) | S8: =$J8*(1+$K8)^(3-1)*(1-$L8)*(1-$M8) | T8: =$J8*(1+$K8)^(4-1)*(1-$L8)*(1-$M8) | U8: =$J8*(1+$K8)^(5-1)*(1-$L8)*(1-$M8)+$O8 | V8: =P8+NPV($N8,Q8:U8) | W8: =IFERROR(IRR(P8:U8,0.1),"")
A9: 5 | B9: =RAND()*(1-2E-6)+1E-6 | C9: =RAND()*(1-2E-6)+1E-6 | D9: =RAND()*(1-2E-6)+1E-6 | E9: =RAND()*(1-2E-6)+1E-6 | F9: =RAND()*(1-2E-6)+1E-6 | G9: =RAND()*(1-2E-6)+1E-6 | H9: =RAND()*(1-2E-6)+1E-6 | I9: =MIN(IF(Supuestos!$H$5="",1E+99,Supuestos!$H$5),MAX(IF(Supuestos!$G$5="",-1E+99,Supuestos!$G$5),IF(Supuestos!$C$5="Normal",NORMINV(B9,Supuestos!$D$5,Supuestos!$E$5),IF(Supuestos!$C$5="Triangular",IF(B9<(Supuestos!$E$5-Supuestos!$D$5)/(Supuestos!$F$5-Supuestos!$D$5),Supuestos!$D$5+SQRT(B9*(Supuestos!$F$5-Supuestos!$D$5)*(Supuestos!$E$5-Supuestos!$D$5)),Supuestos!$F$5-SQRT((1-B9)*(Supuestos!$F$5-Supuestos!$D$5)*(Supuestos!$F$5-Supuestos!$E$5))),IF(Supuestos!$C$5="Uniforme",Supuestos!$D$5+B9*(Supuestos!$E$5-Supuestos!$D$5),IF(Supuestos!$C$5="Lognormal",LOGINV(B9,LN(Supuestos!$D$5)-LN(1+Supuestos!$E$5^2/Supuestos!$D$5^2)/2,SQRT(LN(1+Supuestos!$E$5^2/Supuestos!$D$5^2))),Supuestos!$D$5)))))) | J9: =MIN(IF(Supuestos!$H$6="",1E+99,Supuestos!$H$6),MAX(IF(Supuestos!$G$6="",-1E+99,Supuestos!$G$6),IF(Supuestos!$C$6="Normal",NORMINV(C9,Supuestos!$D$6,Supuestos!$E$6),IF(Supuestos!$C$6="Triangular",IF(C9<(Supuestos!$E$6-Supuestos!$D$6)/(Supuestos!$F$6-Supuestos!$D$6),Supuestos!$D$6+SQRT(C9*(Supuestos!$F$6-Supuestos!$D$6)*(Supuestos!$E$6-Supuestos!$D$6)),Supuestos!$F$6-SQRT((1-C9)*(Supuestos!$F$6-Supuestos!$D$6)*(Supuestos!$F$6-Supuestos!$E$6))),IF(Supuestos!$C$6="Uniforme",Supuestos!$D$6+C9*(Supuestos!$E$6-Supuestos!$D$6),IF(Supuestos!$C$6="Lognormal",LOGINV(C9,LN(Supuestos!$D$6)-LN(1+Supuestos!$E$6^2/Supuestos!$D$6^2)/2,SQRT(LN(1+Supuestos!$E$6^2/Supuestos!$D$6^2))),Supuestos!$D$6)))))) | K9: =MIN(IF(Supuestos!$H$7="",1E+99,Supuestos!$H$7),MAX(IF(Supuestos!$G$7="",-1E+99,Supuestos!$G$7),IF(Supuestos!$C$7="Normal",NORMINV(D9,Supuestos!$D$7,Supuestos!$E$7),IF(Supuestos!$C$7="Triangular",IF(D9<(Supuestos!$E$7-Supuestos!$D$7)/(Supuestos!$F$7-Supuestos!$D$7),Supuestos!$D$7+SQRT(D9*(Supuestos!$F$7-Supuestos!$D$7)*(Supuestos!$E$7-Supuestos!$D$7)),Supuestos!$F$7-SQRT((1-D9)*(Supuestos!$F$7-Supuestos!$D$7)*(Supuestos!$F$7-Supuestos!$E$7))),IF(Supuestos!$C$7="Uniforme",Supuestos!$D$7+D9*(Supuestos!$E$7-Supuestos!$D$7),IF(Supuestos!$C$7="Lognormal",LOGINV(D9,LN(Supuestos!$D$7)-LN(1+Supuestos!$E$7^2/Supuestos!$D$7^2)/2,SQRT(LN(1+Supuestos!$E$7^2/Supuestos!$D$7^2))),Supuestos!$D$7)))))) | L9: =MIN(IF(Supuestos!$H$8="",1E+99,Supuestos!$H$8),MAX(IF(Supuestos!$G$8="",-1E+99,Supuestos!$G$8),IF(Supuestos!$C$8="Normal",NORMINV(E9,Supuestos!$D$8,Supuestos!$E$8),IF(Supuestos!$C$8="Triangular",IF(E9<(Supuestos!$E$8-Supuestos!$D$8)/(Supuestos!$F$8-Supuestos!$D$8),Supuestos!$D$8+SQRT(E9*(Supuestos!$F$8-Supuestos!$D$8)*(Supuestos!$E$8-Supuestos!$D$8)),Supuestos!$F$8-SQRT((1-E9)*(Supuestos!$F$8-Supuestos!$D$8)*(Supuestos!$F$8-Supuestos!$E$8))),IF(Supuestos!$C$8="Uniforme",Supuestos!$D$8+E9*(Supuestos!$E$8-Supuestos!$D$8),IF(Supuestos!$C$8="Lognormal",LOGINV(E9,LN(Supuestos!$D$8)-LN(1+Supuestos!$E$8^2/Supuestos!$D$8^2)/2,SQRT(LN(1+Supuestos!$E$8^2/Supuestos!$D$8^2))),Supuestos!$D$8)))))) | M9: =MIN(IF(Supuestos!$H$9="",1E+99,Supuestos!$H$9),MAX(IF(Supuestos!$G$9="",-1E+99,Supuestos!$G$9),IF(Supuestos!$C$9="Normal",NORMINV(F9,Supuestos!$D$9,Supuestos!$E$9),IF(Supuestos!$C$9="Triangular",IF(F9<(Supuestos!$E$9-Supuestos!$D$9)/(Supuestos!$F$9-Supuestos!$D$9),Supuestos!$D$9+SQRT(F9*(Supuestos!$F$9-Supuestos!$D$9)*(Supuestos!$E$9-Supuestos!$D$9)),Supuestos!$F$9-SQRT((1-F9)*(Supuestos!$F$9-Supuestos!$D$9)*(Supuestos!$F$9-Supuestos!$E$9))),IF(Supuestos!$C$9="Uniforme",Supuestos!$D$9+F9*(Supuestos!$E$9-Supuestos!$D$9),IF(Supuestos!$C$9="Lognormal",LOGINV(F9,LN(Supuestos!$D$9)-LN(1+Supuestos!$E$9^2/Supuestos!$D$9^2)/2,SQRT(LN(1+Supuestos!$E$9^2/Supuestos!$D$9^2))),Supuestos!$D$9)))))) | N9: =MIN(IF(Supuestos!$H$10="",1E+99,Supuestos!$H$10),MAX(IF(Supuestos!$G$10="",-1E+99,Supuestos!$G$10),IF(Supuestos!$C$10="Normal",NORMINV(G9,Supuestos!$D$10,Supuestos!$E$10),IF(Supuestos!$C$10="Triangular",IF(G9<(Supuestos!$E$10-Supuestos!$D$10)/(Supuestos!$F$10-Supuestos!$D$10),Supuestos!$D$10+SQRT(G9*(Supuestos!$F$10-Supuestos!$D$10)*(Supuestos!$E$10-Supuestos!$D$10)),Supuestos!$F$10-SQRT((1-G9)*(Supuestos!$F$10-Supuestos!$D$10)*(Supuestos!$F$10-Supuestos!$E$10))),IF(Supuestos!$C$10="Uniforme",Supuestos!$D$10+G9*(Supuestos!$E$10-Supuestos!$D$10),IF(Supuestos!$C$10="Lognormal",LOGINV(G9,LN(Supuestos!$D$10)-LN(1+Supuestos!$E$10^2/Supuestos!$D$10^2)/2,SQRT(LN(1+Supuestos!$E$10^2/Supuestos!$D$10^2))),Supuestos!$D$10)))))) | O9: =MIN(IF(Supuestos!$H$11="",1E+99,Supuestos!$H$11),MAX(IF(Supuestos!$G$11="",-1E+99,Supuestos!$G$11),IF(Supuestos!$C$11="Normal",NORMINV(H9,Supuestos!$D$11,Supuestos!$E$11),IF(Supuestos!$C$11="Triangular",IF(H9<(Supuestos!$E$11-Supuestos!$D$11)/(Supuestos!$F$11-Supuestos!$D$11),Supuestos!$D$11+SQRT(H9*(Supuestos!$F$11-Supuestos!$D$11)*(Supuestos!$E$11-Supuestos!$D$11)),Supuestos!$F$11-SQRT((1-H9)*(Supuestos!$F$11-Supuestos!$D$11)*(Supuestos!$F$11-Supuestos!$E$11))),IF(Supuestos!$C$11="Uniforme",Supuestos!$D$11+H9*(Supuestos!$E$11-Supuestos!$D$11),IF(Supuestos!$C$11="Lognormal",LOGINV(H9,LN(Supuestos!$D$11)-LN(1+Supuestos!$E$11^2/Supuestos!$D$11^2)/2,SQRT(LN(1+Supuestos!$E$11^2/Supuestos!$D$11^2))),Supuestos!$D$11)))))) | P9: =-I9 | Q9: =$J9*(1+$K9)^(1-1)*(1-$L9)*(1-$M9) | R9: =$J9*(1+$K9)^(2-1)*(1-$L9)*(1-$M9) | S9: =$J9*(1+$K9)^(3-1)*(1-$L9)*(1-$M9) | T9: =$J9*(1+$K9)^(4-1)*(1-$L9)*(1-$M9) | U9: =$J9*(1+$K9)^(5-1)*(1-$L9)*(1-$M9)+$O9 | V9: =P9+NPV($N9,Q9:U9) | W9: =IFERROR(IRR(P9:U9,0.1),"")
A10: 6 | B10: =RAND()*(1-2E-6)+1E-6 | C10: =RAND()*(1-2E-6)+1E-6 | D10: =RAND()*(1-2E-6)+1E-6 | E10: =RAND()*(1-2E-6)+1E-6 | F10: =RAND()*(1-2E-6)+1E-6 | G10: =RAND()*(1-2E-6)+1E-6 | H10: =RAND()*(1-2E-6)+1E-6 | I10: =MIN(IF(Supuestos!$H$5="",1E+99,Supuestos!$H$5),MAX(IF(Supuestos!$G$5="",-1E+99,Supuestos!$G$5),IF(Supuestos!$C$5="Normal",NORMINV(B10,Supuestos!$D$5,Supuestos!$E$5),IF(Supuestos!$C$5="Triangular",IF(B10<(Supuestos!$E$5-Supuestos!$D$5)/(Supuestos!$F$5-Supuestos!$D$5),Supuestos!$D$5+SQRT(B10*(Supuestos!$F$5-Supuestos!$D$5)*(Supuestos!$E$5-Supuestos!$D$5)),Supuestos!$F$5-SQRT((1-B10)*(Supuestos!$F$5-Supuestos!$D$5)*(Supuestos!$F$5-Supuestos!$E$5))),IF(Supuestos!$C$5="Uniforme",Supuestos!$D$5+B10*(Supuestos!$E$5-Supuestos!$D$5),IF(Supuestos!$C$5="Lognormal",LOGINV(B10,LN(Supuestos!$D$5)-LN(1+Supuestos!$E$5^2/Supuestos!$D$5^2)/2,SQRT(LN(1+Supuestos!$E$5^2/Supuestos!$D$5^2))),Supuestos!$D$5)))))) | J10: =MIN(IF(Supuestos!$H$6="",1E+99,Supuestos!$H$6),MAX(IF(Supuestos!$G$6="",-1E+99,Supuestos!$G$6),IF(Supuestos!$C$6="Normal",NORMINV(C10,Supuestos!$D$6,Supuestos!$E$6),IF(Supuestos!$C$6="Triangular",IF(C10<(Supuestos!$E$6-Supuestos!$D$6)/(Supuestos!$F$6-Supuestos!$D$6),Supuestos!$D$6+SQRT(C10*(Supuestos!$F$6-Supuestos!$D$6)*(Supuestos!$E$6-Supuestos!$D$6)),Supuestos!$F$6-SQRT((1-C10)*(Supuestos!$F$6-Supuestos!$D$6)*(Supuestos!$F$6-Supuestos!$E$6))),IF(Supuestos!$C$6="Uniforme",Supuestos!$D$6+C10*(Supuestos!$E$6-Supuestos!$D$6),IF(Supuestos!$C$6="Lognormal",LOGINV(C10,LN(Supuestos!$D$6)-LN(1+Supuestos!$E$6^2/Supuestos!$D$6^2)/2,SQRT(LN(1+Supuestos!$E$6^2/Supuestos!$D$6^2))),Supuestos!$D$6)))))) | K10: =MIN(IF(Supuestos!$H$7="",1E+99,Supuestos!$H$7),MAX(IF(Supuestos!$G$7="",-1E+99,Supuestos!$G$7),IF(Supuestos!$C$7="Normal",NORMINV(D10,Supuestos!$D$7,Supuestos!$E$7),IF(Supuestos!$C$7="Triangular",IF(D10<(Supuestos!$E$7-Supuestos!$D$7)/(Supuestos!$F$7-Supuestos!$D$7),Supuestos!$D$7+SQRT(D10*(Supuestos!$F$7-Supuestos!$D$7)*(Supuestos!$E$7-Supuestos!$D$7)),Supuestos!$F$7-SQRT((1-D10)*(Supuestos!$F$7-Supuestos!$D$7)*(Supuestos!$F$7-Supuestos!$E$7))),IF(Supuestos!$C$7="Uniforme",Supuestos!$D$7+D10*(Supuestos!$E$7-Supuestos!$D$7),IF(Supuestos!$C$7="Lognormal",LOGINV(D10,LN(Supuestos!$D$7)-LN(1+Supuestos!$E$7^2/Supuestos!$D$7^2)/2,SQRT(LN(1+Supuestos!$E$7^2/Supuestos!$D$7^2))),Supuestos!$D$7)))))) | L10: =MIN(IF(Supuestos!$H$8="",1E+99,Supuestos!$H$8),MAX(IF(Supuestos!$G$8="",-1E+99,Supuestos!$G$8),IF(Supuestos!$C$8="Normal",NORMINV(E10,Supuestos!$D$8,Supuestos!$E$8),IF(Supuestos!$C$8="Triangular",IF(E10<(Supuestos!$E$8-Supuestos!$D$8)/(Supuestos!$F$8-Supuestos!$D$8),Supuestos!$D$8+SQRT(E10*(Supuestos!$F$8-Supuestos!$D$8)*(Supuestos!$E$8-Supuestos!$D$8)),Supuestos!$F$8-SQRT((1-E10)*(Supuestos!$F$8-Supuestos!$D$8)*(Supuestos!$F$8-Supuestos!$E$8))),IF(Supuestos!$C$8="Uniforme",Supuestos!$D$8+E10*(Supuestos!$E$8-Supuestos!$D$8),IF(Supuestos!$C$8="Lognormal",LOGINV(E10,LN(Supuestos!$D$8)-LN(1+Supuestos!$E$8^2/Supuestos!$D$8^2)/2,SQRT(LN(1+Supuestos!$E$8^2/Supuestos!$D$8^2))),Supuestos!$D$8)))))) | M10: =MIN(IF(Supuestos!$H$9="",1E+99,Supuestos!$H$9),MAX(IF(Supuestos!$G$9="",-1E+99,Supuestos!$G$9),IF(Supuestos!$C$9="Normal",NORMINV(F10,Supuestos!$D$9,Supuestos!$E$9),IF(Supuestos!$C$9="Triangular",IF(F10<(Supuestos!$E$9-Supuestos!$D$9)/(Supuestos!$F$9-Supuestos!$D$9),Supuestos!$D$9+SQRT(F10*(Supuestos!$F$9-Supuestos!$D$9)*(Supuestos!$E$9-Supuestos!$D$9)),Supuestos!$F$9-SQRT((1-F10)*(Supuestos!$F$9-Supuestos!$D$9)*(Supuestos!$F$9-Supuestos!$E$9))),IF(Supuestos!$C$9="Uniforme",Supuestos!$D$9+F10*(Supuestos!$E$9-Supuestos!$D$9),IF(Supuestos!$C$9="Lognormal",LOGINV(F10,LN(Supuestos!$D$9)-LN(1+Supuestos!$E$9^2/Supuestos!$D$9^2)/2,SQRT(LN(1+Supuestos!$E$9^2/Supuestos!$D$9^2))),Supuestos!$D$9)))))) | N10: =MIN(IF(Supuestos!$H$10="",1E+99,Supuestos!$H$10),MAX(IF(Supuestos!$G$10="",-1E+99,Supuestos!$G$10),IF(Supuestos!$C$10="Normal",NORMINV(G10,Supuestos!$D$10,Supuestos!$E$10),IF(Supuestos!$C$10="Triangular",IF(G10<(Supuestos!$E$10-Supuestos!$D$10)/(Supuestos!$F$10-Supuestos!$D$10),Supuestos!$D$10+SQRT(G10*(Supuestos!$F$10-Supuestos!$D$10)*(Supuestos!$E$10-Supuestos!$D$10)),Supuestos!$F$10-SQRT((1-G10)*(Supuestos!$F$10-Supuestos!$D$10)*(Supuestos!$F$10-Supuestos!$E$10))),IF(Supuestos!$C$10="Uniforme",Supuestos!$D$10+G10*(Supuestos!$E$10-Supuestos!$D$10),IF(Supuestos!$C$10="Lognormal",LOGINV(G10,LN(Supuestos!$D$10)-LN(1+Supuestos!$E$10^2/Supuestos!$D$10^2)/2,SQRT(LN(1+Supuestos!$E$10^2/Supuestos!$D$10^2))),Supuestos!$D$10)))))) | O10: =MIN(IF(Supuestos!$H$11="",1E+99,Supuestos!$H$11),MAX(IF(Supuestos!$G$11="",-1E+99,Supuestos!$G$11),IF(Supuestos!$C$11="Normal",NORMINV(H10,Supuestos!$D$11,Supuestos!$E$11),IF(Supuestos!$C$11="Triangular",IF(H10<(Supuestos!$E$11-Supuestos!$D$11)/(Supuestos!$F$11-Supuestos!$D$11),Supuestos!$D$11+SQRT(H10*(Supuestos!$F$11-Supuestos!$D$11)*(Supuestos!$E$11-Supuestos!$D$11)),Supuestos!$F$11-SQRT((1-H10)*(Supuestos!$F$11-Supuestos!$D$11)*(Supuestos!$F$11-Supuestos!$E$11))),IF(Supuestos!$C$11="Uniforme",Supuestos!$D$11+H10*(Supuestos!$E$11-Supuestos!$D$11),IF(Supuestos!$C$11="Lognormal",LOGINV(H10,LN(Supuestos!$D$11)-LN(1+Supuestos!$E$11^2/Supuestos!$D$11^2)/2,SQRT(LN(1+Supuestos!$E$11^2/Supuestos!$D$11^2))),Supuestos!$D$11)))))) | P10: =-I10 | Q10: =$J10*(1+$K10)^(1-1)*(1-$L10)*(1-$M10) | R10: =$J10*(1+$K10)^(2-1)*(1-$L10)*(1-$M10) | S10: =$J10*(1+$K10)^(3-1)*(1-$L10)*(1-$M10) | T10: =$J10*(1+$K10)^(4-1)*(1-$L10)*(1-$M10) | U10: =$J10*(1+$K10)^(5-1)*(1-$L10)*(1-$M10)+$O10 | V10: =P10+NPV($N10,Q10:U10) | W10: =IFERROR(IRR(P10:U10,0.1),"")
A11: 7 | B11: =RAND()*(1-2E-6)+1E-6 | C11: =RAND()*(1-2E-6)+1E-6 | D11: =RAND()*(1-2E-6)+1E-6 | E11: =RAND()*(1-2E-6)+1E-6 | F11: =RAND()*(1-2E-6)+1E-6 | G11: =RAND()*(1-2E-6)+1E-6 | H11: =RAND()*(1-2E-6)+1E-6 | I11: =MIN(IF(Supuestos!$H$5="",1E+99,Supuestos!$H$5),MAX(IF(Supuestos!$G$5="",-1E+99,Supuestos!$G$5),IF(Supuestos!$C$5="Normal",NORMINV(B11,Supuestos!$D$5,Supuestos!$E$5),IF(Supuestos!$C$5="Triangular",IF(B11<(Supuestos!$E$5-Supuestos!$D$5)/(Supuestos!$F$5-Supuestos!$D$5),Supuestos!$D$5+SQRT(B11*(Supuestos!$F$5-Supuestos!$D$5)*(Supuestos!$E$5-Supuestos!$D$5)),Supuestos!$F$5-SQRT((1-B11)*(Supuestos!$F$5-Supuestos!$D$5)*(Supuestos!$F$5-Supuestos!$E$5))),IF(Supuestos!$C$5="Uniforme",Supuestos!$D$5+B11*(Supuestos!$E$5-Supuestos!$D$5),IF(Supuestos!$C$5="Lognormal",LOGINV(B11,LN(Supuestos!$D$5)-LN(1+Supuestos!$E$5^2/Supuestos!$D$5^2)/2,SQRT(LN(1+Supuestos!$E$5^2/Supuestos!$D$5^2))),Supuestos!$D$5)))))) | J11: =MIN(IF(Supuestos!$H$6="",1E+99,Supuestos!$H$6),MAX(IF(Supuestos!$G$6="",-1E+99,Supuestos!$G$6),IF(Supuestos!$C$6="Normal",NORMINV(C11,Supuestos!$D$6,Supuestos!$E$6),IF(Supuestos!$C$6="Triangular",IF(C11<(Supuestos!$E$6-Supuestos!$D$6)/(Supuestos!$F$6-Supuestos!$D$6),Supuestos!$D$6+SQRT(C11*(Supuestos!$F$6-Supuestos!$D$6)*(Supuestos!$E$6-Supuestos!$D$6)),Supuestos!$F$6-SQRT((1-C11)*(Supuestos!$F$6-Supuestos!$D$6)*(Supuestos!$F$6-Supuestos!$E$6))),IF(Supuestos!$C$6="Uniforme",Supuestos!$D$6+C11*(Supuestos!$E$6-Supuestos!$D$6),IF(Supuestos!$C$6="Lognormal",LOGINV(C11,LN(Supuestos!$D$6)-LN(1+Supuestos!$E$6^2/Supuestos!$D$6^2)/2,SQRT(LN(1+Supuestos!$E$6^2/Supuestos!$D$6^2))),Supuestos!$D$6)))))) | K11: =MIN(IF(Supuestos!$H$7="",1E+99,Supuestos!$H$7),MAX(IF(Supuestos!$G$7="",-1E+99,Supuestos!$G$7),IF(Supuestos!$C$7="Normal",NORMINV(D11,Supuestos!$D$7,Supuestos!$E$7),IF(Supuestos!$C$7="Triangular",IF(D11<(Supuestos!$E$7-Supuestos!$D$7)/(Supuestos!$F$7-Supuestos!$D$7),Supuestos!$D$7+SQRT(D11*(Supuestos!$F$7-Supuestos!$D$7)*(Supuestos!$E$7-Supuestos!$D$7)),Supuestos!$F$7-SQRT((1-D11)*(Supuestos!$F$7-Supuestos!$D$7)*(Supuestos!$F$7-Supuestos!$E$7))),IF(Supuestos!$C$7="Uniforme",Supuestos!$D$7+D11*(Supuestos!$E$7-Supuestos!$D$7),IF(Supuestos!$C$7="Lognormal",LOGINV(D11,LN(Supuestos!$D$7)-LN(1+Supuestos!$E$7^2/Supuestos!$D$7^2)/2,SQRT(LN(1+Supuestos!$E$7^2/Supuestos!$D$7^2))),Supuestos!$D$7)))))) | L11: =MIN(IF(Supuestos!$H$8="",1E+99,Supuestos!$H$8),MAX(IF(Supuestos!$G$8="",-1E+99,Supuestos!$G$8),IF(Supuestos!$C$8="Normal",NORMINV(E11,Supuestos!$D$8,Supuestos!$E$8),IF(Supuestos!$C$8="Triangular",IF(E11<(Supuestos!$E$8-Supuestos!$D$8)/(Supuestos!$F$8-Supuestos!$D$8),Supuestos!$D$8+SQRT(E11*(Supuestos!$F$8-Supuestos!$D$8)*(Supuestos!$E$8-Supuestos!$D$8)),Supuestos!$F$8-SQRT((1-E11)*(Supuestos!$F$8-Supuestos!$D$8)*(Supuestos!$F$8-Supuestos!$E$8))),IF(Supuestos!$C$8="Uniforme",Supuestos!$D$8+E11*(Supuestos!$E$8-Supuestos!$D$8),IF(Supuestos!$C$8="Lognormal",LOGINV(E11,LN(Supuestos!$D$8)-LN(1+Supuestos!$E$8^2/Supuestos!$D$8^2)/2,SQRT(LN(1+Supuestos!$E$8^2/Supuestos!$D$8^2))),Supuestos!$D$8)))))) | M11: =MIN(IF(Supuestos!$H$9="",1E+99,Supuestos!$H$9),MAX(IF(Supuestos!$G$9="",-1E+99,Supuestos!$G$9),IF(Supuestos!$C$9="Normal",NORMINV(F11,Supuestos!$D$9,Supuestos!$E$9),IF(Supuestos!$C$9="Triangular",IF(F11<(Supuestos!$E$9-Supuestos!$D$9)/(Supuestos!$F$9-Supuestos!$D$9),Supuestos!$D$9+SQRT(F11*(Supuestos!$F$9-Supuestos!$D$9)*(Supuestos!$E$9-Supuestos!$D$9)),Supuestos!$F$9-SQRT((1-F11)*(Supuestos!$F$9-Supuestos!$D$9)*(Supuestos!$F$9-Supuestos!$E$9))),IF(Supuestos!$C$9="Uniforme",Supuestos!$D$9+F11*(Supuestos!$E$9-Supuestos!$D$9),IF(Supuestos!$C$9="Lognormal",LOGINV(F11,LN(Supuestos!$D$9)-LN(1+Supuestos!$E$9^2/Supuestos!$D$9^2)/2,SQRT(LN(1+Supuestos!$E$9^2/Supuestos!$D$9^2))),Supuestos!$D$9)))))) | N11: =MIN(IF(Supuestos!$H$10="",1E+99,Supuestos!$H$10),MAX(IF(Supuestos!$G$10="",-1E+99,Supuestos!$G$10),IF(Supuestos!$C$10="Normal",NORMINV(G11,Supuestos!$D$10,Supuestos!$E$10),IF(Supuestos!$C$10="Triangular",IF(G11<(Supuestos!$E$10-Supuestos!$D$10)/(Supuestos!$F$10-Supuestos!$D$10),Supuestos!$D$10+SQRT(G11*(Supuestos!$F$10-Supuestos!$D$10)*(Supuestos!$E$10-Supuestos!$D$10)),Supuestos!$F$10-SQRT((1-G11)*(Supuestos!$F$10-Supuestos!$D$10)*(Supuestos!$F$10-Supuestos!$E$10))),IF(Supuestos!$C$10="Uniforme",Supuestos!$D$10+G11*(Supuestos!$E$10-Supuestos!$D$10),IF(Supuestos!$C$10="Lognormal",LOGINV(G11,LN(Supuestos!$D$10)-LN(1+Supuestos!$E$10^2/Supuestos!$D$10^2)/2,SQRT(LN(1+Supuestos!$E$10^2/Supuestos!$D$10^2))),Supuestos!$D$10)))))) | O11: =MIN(IF(Supuestos!$H$11="",1E+99,Supuestos!$H$11),MAX(IF(Supuestos!$G$11="",-1E+99,Supuestos!$G$11),IF(Supuestos!$C$11="Normal",NORMINV(H11,Supuestos!$D$11,Supuestos!$E$11),IF(Supuestos!$C$11="Triangular",IF(H11<(Supuestos!$E$11-Supuestos!$D$11)/(Supuestos!$F$11-Supuestos!$D$11),Supuestos!$D$11+SQRT(H11*(Supuestos!$F$11-Supuestos!$D$11)*(Supuestos!$E$11-Supuestos!$D$11)),Supuestos!$F$11-SQRT((1-H11)*(Supuestos!$F$11-Supuestos!$D$11)*(Supuestos!$F$11-Supuestos!$E$11))),IF(Supuestos!$C$11="Uniforme",Supuestos!$D$11+H11*(Supuestos!$E$11-Supuestos!$D$11),IF(Supuestos!$C$11="Lognormal",LOGINV(H11,LN(Supuestos!$D$11)-LN(1+Supuestos!$E$11^2/Supuestos!$D$11^2)/2,SQRT(LN(1+Supuestos!$E$11^2/Supuestos!$D$11^2))),Supuestos!$D$11)))))) | P11: =-I11 | Q11: =$J11*(1+$K11)^(1-1)*(1-$L11)*(1-$M11) | R11: =$J11*(1+$K11)^(2-1)*(1-$L11)*(1-$M11) | S11: =$J11*(1+$K11)^(3-1)*(1-$L11)*(1-$M11) | T11: =$J11*(1+$K11)^(4-1)*(1-$L11)*(1-$M11) | U11: =$J11*(1+$K11)^(5-1)*(1-$L11)*(1-$M11)+$O11 | V11: =P11+NPV($N11,Q11:U11) | W11: =IFERROR(IRR(P11:U11,0.1),"")
A12: 8 | B12: =RAND()*(1-2E-6)+1E-6 | C12: =RAND()*(1-2E-6)+1E-6 | D12: =RAND()*(1-2E-6)+1E-6 | E12: =RAND()*(1-2E-6)+1E-6 | F12: =RAND()*(1-2E-6)+1E-6 | G12: =RAND()*(1-2E-6)+1E-6 | H12: =RAND()*(1-2E-6)+1E-6 | I12: =MIN(IF(Supuestos!$H$5="",1E+99,Supuestos!$H$5),MAX(IF(Supuestos!$G$5="",-1E+99,Supuestos!$G$5),IF(Supuestos!$C$5="Normal",NORMINV(B12,Supuestos!$D$5,Supuestos!$E$5),IF(Supuestos!$C$5="Triangular",IF(B12<(Supuestos!$E$5-Supuestos!$D$5)/(Supuestos!$F$5-Supuestos!$D$5),Supuestos!$D$5+SQRT(B12*(Supuestos!$F$5-Supuestos!$D$5)*(Supuestos!$E$5-Supuestos!$D$5)),Supuestos!$F$5-SQRT((1-B12)*(Supuestos!$F$5-Supuestos!$D$5)*(Supuestos!$F$5-Supuestos!$E$5))),IF(Supuestos!$C$5="Uniforme",Supuestos!$D$5+B12*(Supuestos!$E$5-Supuestos!$D$5),IF(Supuestos!$C$5="Lognormal",LOGINV(B12,LN(Supuestos!$D$5)-LN(1+Supuestos!$E$5^2/Supuestos!$D$5^2)/2,SQRT(LN(1+Supuestos!$E$5^2/Supuestos!$D$5^2))),Supuestos!$D$5)))))) | J12: =MIN(IF(Supuestos!$H$6="",1E+99,Supuestos!$H$6),MAX(IF(Supuestos!$G$6="",-1E+99,Supuestos!$G$6),IF(Supuestos!$C$6="Normal",NORMINV(C12,Supuestos!$D$6,Supuestos!$E$6),IF(Supuestos!$C$6="Triangular",IF(C12<(Supuestos!$E$6-Supuestos!$D$6)/(Supuestos!$F$6-Supuestos!$D$6),Supuestos!$D$6+SQRT(C12*(Supuestos!$F$6-Supuestos!$D$6)*(Supuestos!$E$6-Supuestos!$D$6)),Supuestos!$F$6-SQRT((1-C12)*(Supuestos!$F$6-Supuestos!$D$6)*(Supuestos!$F$6-Supuestos!$E$6))),IF(Supuestos!$C$6="Uniforme",Supuestos!$D$6+C12*(Supuestos!$E$6-Supuestos!$D$6),IF(Supuestos!$C$6="Lognormal",LOGINV(C12,LN(Supuestos!$D$6)-LN(1+Supuestos!$E$6^2/Supuestos!$D$6^2)/2,SQRT(LN(1+Supuestos!$E$6^2/Supuestos!$D$6^2))),Supuestos!$D$6)))))) | K12: =MIN(IF(Supuestos!$H$7="",1E+99,Supuestos!$H$7),MAX(IF(Supuestos!$G$7="",-1E+99,Supuestos!$G$7),IF(Supuestos!$C$7="Normal",NORMINV(D12,Supuestos!$D$7,Supuestos!$E$7),IF(Supuestos!$C$7="Triangular",IF(D12<(Supuestos!$E$7-Supuestos!$D$7)/(Supuestos!$F$7-Supuestos!$D$7),Supuestos!$D$7+SQRT(D12*(Supuestos!$F$7-Supuestos!$D$7)*(Supuestos!$E$7-Supuestos!$D$7)),Supuestos!$F$7-SQRT((1-D12)*(Supuestos!$F$7-Supuestos!$D$7)*(Supuestos!$F$7-Supuestos!$E$7))),IF(Supuestos!$C$7="Uniforme",Supuestos!$D$7+D12*(Supuestos!$E$7-Supuestos!$D$7),IF(Supuestos!$C$7="Lognormal",LOGINV(D12,LN(Supuestos!$D$7)-LN(1+Supuestos!$E$7^2/Supuestos!$D$7^2)/2,SQRT(LN(1+Supuestos!$E$7^2/Supuestos!$D$7^2))),Supuestos!$D$7)))))) | L12: =MIN(IF(Supuestos!$H$8="",1E+99,Supuestos!$H$8),MAX(IF(Supuestos!$G$8="",-1E+99,Supuestos!$G$8),IF(Supuestos!$C$8="Normal",NORMINV(E12,Supuestos!$D$8,Supuestos!$E$8),IF(Supuestos!$C$8="Triangular",IF(E12<(Supuestos!$E$8-Supuestos!$D$8)/(Supuestos!$F$8-Supuestos!$D$8),Supuestos!$D$8+SQRT(E12*(Supuestos!$F$8-Supuestos!$D$8)*(Supuestos!$E$8-Supuestos!$D$8)),Supuestos!$F$8-SQRT((1-E12)*(Supuestos!$F$8-Supuestos!$D$8)*(Supuestos!$F$8-Supuestos!$E$8))),IF(Supuestos!$C$8="Uniforme",Supuestos!$D$8+E12*(Supuestos!$E$8-Supuestos!$D$8),IF(Supuestos!$C$8="Lognormal",LOGINV(E12,LN(Supuestos!$D$8)-LN(1+Supuestos!$E$8^2/Supuestos!$D$8^2)/2,SQRT(LN(1+Supuestos!$E$8^2/Supuestos!$D$8^2))),Supuestos!$D$8)))))) | M12: =MIN(IF(Supuestos!$H$9="",1E+99,Supuestos!$H$9),MAX(IF(Supuestos!$G$9="",-1E+99,Supuestos!$G$9),IF(Supuestos!$C$9="Normal",NORMINV(F12,Supuestos!$D$9,Supuestos!$E$9),IF(Supuestos!$C$9="Triangular",IF(F12<(Supuestos!$E$9-Supuestos!$D$9)/(Supuestos!$F$9-Supuestos!$D$9),Supuestos!$D$9+SQRT(F12*(Supuestos!$F$9-Supuestos!$D$9)*(Supuestos!$E$9-Supuestos!$D$9)),Supuestos!$F$9-SQRT((1-F12)*(Supuestos!$F$9-Supuestos!$D$9)*(Supuestos!$F$9-Supuestos!$E$9))),IF(Supuestos!$C$9="Uniforme",Supuestos!$D$9+F12*(Supuestos!$E$9-Supuestos!$D$9),IF(Supuestos!$C$9="Lognormal",LOGINV(F12,LN(Supuestos!$D$9)-LN(1+Supuestos!$E$9^2/Supuestos!$D$9^2)/2,SQRT(LN(1+Supuestos!$E$9^2/Supuestos!$D$9^2))),Supuestos!$D$9)))))) | N12: =MIN(IF(Supuestos!$H$10="",1E+99,Supuestos!$H$10),MAX(IF(Supuestos!$G$10="",-1E+99,Supuestos!$G$10),IF(Supuestos!$C$10="Normal",NORMINV(G12,Supuestos!$D$10,Supuestos!$E$10),IF(Supuestos!$C$10="Triangular",IF(G12<(Supuestos!$E$10-Supuestos!$D$10)/(Supuestos!$F$10-Supuestos!$D$10),Supuestos!$D$10+SQRT(G12*(Supuestos!$F$10-Supuestos!$D$10)*(Supuestos!$E$10-Supuestos!$D$10)),Supuestos!$F$10-SQRT((1-G12)*(Supuestos!$F$10-Supuestos!$D$10)*(Supuestos!$F$10-Supuestos!$E$10))),IF(Supuestos!$C$10="Uniforme",Supuestos!$D$10+G12*(Supuestos!$E$10-Supuestos!$D$10),IF(Supuestos!$C$10="Lognormal",LOGINV(G12,LN(Supuestos!$D$10)-LN(1+Supuestos!$E$10^2/Supuestos!$D$10^2)/2,SQRT(LN(1+Supuestos!$E$10^2/Supuestos!$D$10^2))),Supuestos!$D$10)))))) | O12: =MIN(IF(Supuestos!$H$11="",1E+99,Supuestos!$H$11),MAX(IF(Supuestos!$G$11="",-1E+99,Supuestos!$G$11),IF(Supuestos!$C$11="Normal",NORMINV(H12,Supuestos!$D$11,Supuestos!$E$11),IF(Supuestos!$C$11="Triangular",IF(H12<(Supuestos!$E$11-Supuestos!$D$11)/(Supuestos!$F$11-Supuestos!$D$11),Supuestos!$D$11+SQRT(H12*(Supuestos!$F$11-Supuestos!$D$11)*(Supuestos!$E$11-Supuestos!$D$11)),Supuestos!$F$11-SQRT((1-H12)*(Supuestos!$F$11-Supuestos!$D$11)*(Supuestos!$F$11-Supuestos!$E$11))),IF(Supuestos!$C$11="Uniforme",Supuestos!$D$11+H12*(Supuestos!$E$11-Supuestos!$D$11),IF(Supuestos!$C$11="Lognormal",LOGINV(H12,LN(Supuestos!$D$11)-LN(1+Supuestos!$E$11^2/Supuestos!$D$11^2)/2,SQRT(LN(1+Supuestos!$E$11^2/Supuestos!$D$11^2))),Supuestos!$D$11)))))) | P12: =-I12 | Q12: =$J12*(1+$K12)^(1-1)*(1-$L12)*(1-$M12) | R12: =$J12*(1+$K12)^(2-1)*(1-$L12)*(1-$M12) | S12: =$J12*(1+$K12)^(3-1)*(1-$L12)*(1-$M12) | T12: =$J12*(1+$K12)^(4-1)*(1-$L12)*(1-$M12) | U12: =$J12*(1+$K12)^(5-1)*(1-$L12)*(1-$M12)+$O12 | V12: =P12+NPV($N12,Q12:U12) | W12: =IFERROR(IRR(P12:U12,0.1),"")
